PS D:\test-new-git\onlineProctoring\onlinetestcreationbackend-main> python manage.py runserver
Watching for file changes with StatReloader
Performing system checks...

System check identified no issues (0 silenced).
June 16, 2025 - 23:39:40
Django version 5.1.6, using settings 'Django_project.settings'
Starting ASGI/Daphne version 4.1.2 development server at http://127.0.0.1:8000/
Quit the server with CTRL-BREAK.
Internal Server Error: /api/tests/
Traceback (most recent call last):
  File "C:\Users\yunus.k\AppData\Local\Programs\Python\Python311\Lib\site-packages\django\db\backends\utils.py", line 105, in _execute
    return self.cursor.execute(sql, params)
           ^^^^^^^^^^^^^^^^^^^^^^^^^^^^^^^^
  File "C:\Users\yunus.k\AppData\Local\Programs\Python\Python311\Lib\site-packages\django\db\backends\sqlite3\base.py", line 354, in execute
    return super().execute(query, params)
           ^^^^^^^^^^^^^^^^^^^^^^^^^^^^^^
sqlite3.IntegrityError: NOT NULL constraint failed: blog_test.owner_id

The above exception was the direct cause of the following exception:

Traceback (most recent call last):
  File "C:\Users\yunus.k\AppData\Local\Programs\Python\Python311\Lib\site-packages\asgiref\sync.py", line 518, in thread_handler    
    raise exc_info[1]
  File "C:\Users\yunus.k\AppData\Local\Programs\Python\Python311\Lib\site-packages\django\core\handlers\exception.py", line 42, in inner
    response = await get_response(request)
               ^^^^^^^^^^^^^^^^^^^^^^^^^^^
  File "C:\Users\yunus.k\AppData\Local\Programs\Python\Python311\Lib\site-packages\asgiref\sync.py", line 518, in thread_handler    
    raise exc_info[1]
  File "C:\Users\yunus.k\AppData\Local\Programs\Python\Python311\Lib\site-packages\django\core\handlers\base.py", line 253, in _get_response_async
    response = await wrapped_callback(
               ^^^^^^^^^^^^^^^^^^^^^^^
  File "C:\Users\yunus.k\AppData\Local\Programs\Python\Python311\Lib\site-packages\asgiref\sync.py", line 468, in __call__
    ret = await asyncio.shield(exec_coro)
          ^^^^^^^^^^^^^^^^^^^^^^^^^^^^^^^
  File "C:\Users\yunus.k\AppData\Local\Programs\Python\Python311\Lib\site-packages\asgiref\current_thread_executor.py", line 40, in run
    result = self.fn(*self.args, **self.kwargs)
             ^^^^^^^^^^^^^^^^^^^^^^^^^^^^^^^^^^
  File "C:\Users\yunus.k\AppData\Local\Programs\Python\Python311\Lib\site-packages\asgiref\sync.py", line 522, in thread_handler    
    return func(*args, **kwargs)
           ^^^^^^^^^^^^^^^^^^^^^
  File "C:\Users\yunus.k\AppData\Local\Programs\Python\Python311\Lib\site-packages\django\views\decorators\csrf.py", line 65, in _view_wrapper
    return view_func(request, *args, **kwargs)
           ^^^^^^^^^^^^^^^^^^^^^^^^^^^^^^^^^^^
  File "C:\Users\yunus.k\AppData\Local\Programs\Python\Python311\Lib\site-packages\rest_framework\viewsets.py", line 124, in view   
    return self.dispatch(request, *args, **kwargs)
           ^^^^^^^^^^^^^^^^^^^^^^^^^^^^^^^^^^^^^^^
  File "C:\Users\yunus.k\AppData\Local\Programs\Python\Python311\Lib\site-packages\rest_framework\views.py", line 509, in dispatch  
    response = self.handle_exception(exc)
               ^^^^^^^^^^^^^^^^^^^^^^^^^^
  File "C:\Users\yunus.k\AppData\Local\Programs\Python\Python311\Lib\site-packages\rest_framework\views.py", line 469, in handle_exception
    self.raise_uncaught_exception(exc)
  File "C:\Users\yunus.k\AppData\Local\Programs\Python\Python311\Lib\site-packages\rest_framework\views.py", line 480, in raise_uncaught_exception
    raise exc
  File "C:\Users\yunus.k\AppData\Local\Programs\Python\Python311\Lib\site-packages\rest_framework\views.py", line 506, in dispatch  
    response = handler(request, *args, **kwargs)
               ^^^^^^^^^^^^^^^^^^^^^^^^^^^^^^^^^
  File "C:\Users\yunus.k\AppData\Local\Programs\Python\Python311\Lib\site-packages\rest_framework\mixins.py", line 19, in create    
    self.perform_create(serializer)
  File "C:\Users\yunus.k\AppData\Local\Programs\Python\Python311\Lib\site-packages\rest_framework\mixins.py", line 24, in perform_create
    serializer.save()
  File "C:\Users\yunus.k\AppData\Local\Programs\Python\Python311\Lib\site-packages\rest_framework\serializers.py", line 208, in save
    self.instance = self.create(validated_data)
                    ^^^^^^^^^^^^^^^^^^^^^^^^^^^
  File "D:\test-new-git\onlineProctoring\onlinetestcreationbackend-main\blog\serializers.py", line 263, in create
    test = Test.objects.create(**validated_data)
           ^^^^^^^^^^^^^^^^^^^^^^^^^^^^^^^^^^^^^
  File "C:\Users\yunus.k\AppData\Local\Programs\Python\Python311\Lib\site-packages\django\db\models\manager.py", line 87, in manager_method
    return getattr(self.get_queryset(), name)(*args, **kwargs)
           ^^^^^^^^^^^^^^^^^^^^^^^^^^^^^^^^^^^^^^^^^^^^^^^^^^^
  File "C:\Users\yunus.k\AppData\Local\Programs\Python\Python311\Lib\site-packages\django\db\models\query.py", line 679, in create  
    obj.save(force_insert=True, using=self.db)
  File "D:\test-new-git\onlineProctoring\onlinetestcreationbackend-main\blog\models.py", line 90, in save
    super().save(*args, **kwargs)
  File "C:\Users\yunus.k\AppData\Local\Programs\Python\Python311\Lib\site-packages\django\db\models\base.py", line 892, in save     
    self.save_base(
  File "C:\Users\yunus.k\AppData\Local\Programs\Python\Python311\Lib\site-packages\django\db\models\base.py", line 998, in save_base
    updated = self._save_table(
              ^^^^^^^^^^^^^^^^^
  File "C:\Users\yunus.k\AppData\Local\Programs\Python\Python311\Lib\site-packages\django\db\models\base.py", line 1161, in _save_table
    results = self._do_insert(
              ^^^^^^^^^^^^^^^^
  File "C:\Users\yunus.k\AppData\Local\Programs\Python\Python311\Lib\site-packages\django\db\models\base.py", line 1202, in _do_insert
    return manager._insert(
           ^^^^^^^^^^^^^^^^
  File "C:\Users\yunus.k\AppData\Local\Programs\Python\Python311\Lib\site-packages\django\db\models\manager.py", line 87, in manager_method
    return getattr(self.get_queryset(), name)(*args, **kwargs)
           ^^^^^^^^^^^^^^^^^^^^^^^^^^^^^^^^^^^^^^^^^^^^^^^^^^^
  File "C:\Users\yunus.k\AppData\Local\Programs\Python\Python311\Lib\site-packages\django\db\models\query.py", line 1847, in _insert
    return query.get_compiler(using=using).execute_sql(returning_fields)
           ^^^^^^^^^^^^^^^^^^^^^^^^^^^^^^^^^^^^^^^^^^^^^^^^^^^^^^^^^^^^^
  File "C:\Users\yunus.k\AppData\Local\Programs\Python\Python311\Lib\site-packages\django\db\models\sql\compiler.py", line 1836, in execute_sql
    cursor.execute(sql, params)
  File "C:\Users\yunus.k\AppData\Local\Programs\Python\Python311\Lib\site-packages\django\db\backends\utils.py", line 122, in execute
    return super().execute(sql, params)
           ^^^^^^^^^^^^^^^^^^^^^^^^^^^^
  File "C:\Users\yunus.k\AppData\Local\Programs\Python\Python311\Lib\site-packages\django\db\backends\utils.py", line 79, in execute
    return self._execute_with_wrappers(
           ^^^^^^^^^^^^^^^^^^^^^^^^^^^^
  File "C:\Users\yunus.k\AppData\Local\Programs\Python\Python311\Lib\site-packages\django\db\backends\utils.py", line 92, in _execute_with_wrappers
    return executor(sql, params, many, context)
           ^^^^^^^^^^^^^^^^^^^^^^^^^^^^^^^^^^^^
  File "C:\Users\yunus.k\AppData\Local\Programs\Python\Python311\Lib\site-packages\django\db\backends\utils.py", line 100, in _execute
    with self.db.wrap_database_errors:
  File "C:\Users\yunus.k\AppData\Local\Programs\Python\Python311\Lib\site-packages\django\db\utils.py", line 91, in __exit__        
    raise dj_exc_value.with_traceback(traceback) from exc_value
  File "C:\Users\yunus.k\AppData\Local\Programs\Python\Python311\Lib\site-packages\django\db\backends\utils.py", line 105, in _execute
    return self.cursor.execute(sql, params)
           ^^^^^^^^^^^^^^^^^^^^^^^^^^^^^^^^
  File "C:\Users\yunus.k\AppData\Local\Programs\Python\Python311\Lib\site-packages\django\db\backends\sqlite3\base.py", line 354, in execute
    return super().execute(query, params)
           ^^^^^^^^^^^^^^^^^^^^^^^^^^^^^^
django.db.utils.IntegrityError: NOT NULL constraint failed: blog_test.owner_id
HTTP POST /api/tests/ 500 [0.29, 127.0.0.1:57225]
HTTP GET /api/questions/ 200 [0.06, 127.0.0.1:57244]
HTTP GET /api/questions/ 200 [0.07, 127.0.0.1:57244]
Internal Server Error: /api/tests/
Traceback (most recent call last):
  File "C:\Users\yunus.k\AppData\Local\Programs\Python\Python311\Lib\site-packages\django\db\backends\utils.py", line 105, in _execute
    return self.cursor.execute(sql, params)
           ^^^^^^^^^^^^^^^^^^^^^^^^^^^^^^^^
  File "C:\Users\yunus.k\AppData\Local\Programs\Python\Python311\Lib\site-packages\django\db\backends\sqlite3\base.py", line 354, in execute
    return super().execute(query, params)
           ^^^^^^^^^^^^^^^^^^^^^^^^^^^^^^
sqlite3.IntegrityError: NOT NULL constraint failed: blog_test.owner_id

The above exception was the direct cause of the following exception:

Traceback (most recent call last):
  File "C:\Users\yunus.k\AppData\Local\Programs\Python\Python311\Lib\site-packages\asgiref\sync.py", line 518, in thread_handler    
    raise exc_info[1]
  File "C:\Users\yunus.k\AppData\Local\Programs\Python\Python311\Lib\site-packages\django\core\handlers\exception.py", line 42, in inner
    response = await get_response(request)
               ^^^^^^^^^^^^^^^^^^^^^^^^^^^
  File "C:\Users\yunus.k\AppData\Local\Programs\Python\Python311\Lib\site-packages\asgiref\sync.py", line 518, in thread_handler    
    raise exc_info[1]
  File "C:\Users\yunus.k\AppData\Local\Programs\Python\Python311\Lib\site-packages\django\core\handlers\base.py", line 253, in _get_response_async
    response = await wrapped_callback(
               ^^^^^^^^^^^^^^^^^^^^^^^
  File "C:\Users\yunus.k\AppData\Local\Programs\Python\Python311\Lib\site-packages\asgiref\sync.py", line 468, in __call__
    ret = await asyncio.shield(exec_coro)
          ^^^^^^^^^^^^^^^^^^^^^^^^^^^^^^^
  File "C:\Users\yunus.k\AppData\Local\Programs\Python\Python311\Lib\site-packages\asgiref\current_thread_executor.py", line 40, in run
    result = self.fn(*self.args, **self.kwargs)
             ^^^^^^^^^^^^^^^^^^^^^^^^^^^^^^^^^^
  File "C:\Users\yunus.k\AppData\Local\Programs\Python\Python311\Lib\site-packages\asgiref\sync.py", line 522, in thread_handler    
    return func(*args, **kwargs)
           ^^^^^^^^^^^^^^^^^^^^^
  File "C:\Users\yunus.k\AppData\Local\Programs\Python\Python311\Lib\site-packages\django\views\decorators\csrf.py", line 65, in _view_wrapper
    return view_func(request, *args, **kwargs)
           ^^^^^^^^^^^^^^^^^^^^^^^^^^^^^^^^^^^
  File "C:\Users\yunus.k\AppData\Local\Programs\Python\Python311\Lib\site-packages\rest_framework\viewsets.py", line 124, in view   
    return self.dispatch(request, *args, **kwargs)
           ^^^^^^^^^^^^^^^^^^^^^^^^^^^^^^^^^^^^^^^
  File "C:\Users\yunus.k\AppData\Local\Programs\Python\Python311\Lib\site-packages\rest_framework\views.py", line 509, in dispatch  
    response = self.handle_exception(exc)
               ^^^^^^^^^^^^^^^^^^^^^^^^^^
  File "C:\Users\yunus.k\AppData\Local\Programs\Python\Python311\Lib\site-packages\rest_framework\views.py", line 469, in handle_exception
    self.raise_uncaught_exception(exc)
  File "C:\Users\yunus.k\AppData\Local\Programs\Python\Python311\Lib\site-packages\rest_framework\views.py", line 480, in raise_uncaught_exception
    raise exc
  File "C:\Users\yunus.k\AppData\Local\Programs\Python\Python311\Lib\site-packages\rest_framework\views.py", line 506, in dispatch  
    response = handler(request, *args, **kwargs)
               ^^^^^^^^^^^^^^^^^^^^^^^^^^^^^^^^^
  File "C:\Users\yunus.k\AppData\Local\Programs\Python\Python311\Lib\site-packages\rest_framework\mixins.py", line 19, in create    
    self.perform_create(serializer)
  File "C:\Users\yunus.k\AppData\Local\Programs\Python\Python311\Lib\site-packages\rest_framework\mixins.py", line 24, in perform_create
    serializer.save()
  File "C:\Users\yunus.k\AppData\Local\Programs\Python\Python311\Lib\site-packages\rest_framework\serializers.py", line 208, in save
    self.instance = self.create(validated_data)
                    ^^^^^^^^^^^^^^^^^^^^^^^^^^^
  File "D:\test-new-git\onlineProctoring\onlinetestcreationbackend-main\blog\serializers.py", line 263, in create
    test = Test.objects.create(**validated_data)
           ^^^^^^^^^^^^^^^^^^^^^^^^^^^^^^^^^^^^^
  File "C:\Users\yunus.k\AppData\Local\Programs\Python\Python311\Lib\site-packages\django\db\models\manager.py", line 87, in manager_method
    return getattr(self.get_queryset(), name)(*args, **kwargs)
           ^^^^^^^^^^^^^^^^^^^^^^^^^^^^^^^^^^^^^^^^^^^^^^^^^^^
  File "C:\Users\yunus.k\AppData\Local\Programs\Python\Python311\Lib\site-packages\django\db\models\query.py", line 679, in create  
    obj.save(force_insert=True, using=self.db)
  File "D:\test-new-git\onlineProctoring\onlinetestcreationbackend-main\blog\models.py", line 90, in save
    super().save(*args, **kwargs)
  File "C:\Users\yunus.k\AppData\Local\Programs\Python\Python311\Lib\site-packages\django\db\models\base.py", line 892, in save     
    self.save_base(
  File "C:\Users\yunus.k\AppData\Local\Programs\Python\Python311\Lib\site-packages\django\db\models\base.py", line 998, in save_base
    updated = self._save_table(
              ^^^^^^^^^^^^^^^^^
  File "C:\Users\yunus.k\AppData\Local\Programs\Python\Python311\Lib\site-packages\django\db\models\base.py", line 1161, in _save_table
    results = self._do_insert(
              ^^^^^^^^^^^^^^^^
  File "C:\Users\yunus.k\AppData\Local\Programs\Python\Python311\Lib\site-packages\django\db\models\base.py", line 1202, in _do_insert
    return manager._insert(
           ^^^^^^^^^^^^^^^^
  File "C:\Users\yunus.k\AppData\Local\Programs\Python\Python311\Lib\site-packages\django\db\models\manager.py", line 87, in manager_method
    return getattr(self.get_queryset(), name)(*args, **kwargs)
           ^^^^^^^^^^^^^^^^^^^^^^^^^^^^^^^^^^^^^^^^^^^^^^^^^^^
  File "C:\Users\yunus.k\AppData\Local\Programs\Python\Python311\Lib\site-packages\django\db\models\query.py", line 1847, in _insert
    return query.get_compiler(using=using).execute_sql(returning_fields)
           ^^^^^^^^^^^^^^^^^^^^^^^^^^^^^^^^^^^^^^^^^^^^^^^^^^^^^^^^^^^^^
  File "C:\Users\yunus.k\AppData\Local\Programs\Python\Python311\Lib\site-packages\django\db\models\sql\compiler.py", line 1836, in execute_sql
    cursor.execute(sql, params)
  File "C:\Users\yunus.k\AppData\Local\Programs\Python\Python311\Lib\site-packages\django\db\backends\utils.py", line 122, in execute
    return super().execute(sql, params)
           ^^^^^^^^^^^^^^^^^^^^^^^^^^^^
  File "C:\Users\yunus.k\AppData\Local\Programs\Python\Python311\Lib\site-packages\django\db\backends\utils.py", line 79, in execute
    return self._execute_with_wrappers(
           ^^^^^^^^^^^^^^^^^^^^^^^^^^^^
  File "C:\Users\yunus.k\AppData\Local\Programs\Python\Python311\Lib\site-packages\django\db\backends\utils.py", line 92, in _execute_with_wrappers
    return executor(sql, params, many, context)
           ^^^^^^^^^^^^^^^^^^^^^^^^^^^^^^^^^^^^
  File "C:\Users\yunus.k\AppData\Local\Programs\Python\Python311\Lib\site-packages\django\db\backends\utils.py", line 100, in _execute
    with self.db.wrap_database_errors:
  File "C:\Users\yunus.k\AppData\Local\Programs\Python\Python311\Lib\site-packages\django\db\utils.py", line 91, in __exit__        
    raise dj_exc_value.with_traceback(traceback) from exc_value
  File "C:\Users\yunus.k\AppData\Local\Programs\Python\Python311\Lib\site-packages\django\db\backends\utils.py", line 105, in _execute
    return self.cursor.execute(sql, params)
           ^^^^^^^^^^^^^^^^^^^^^^^^^^^^^^^^
  File "C:\Users\yunus.k\AppData\Local\Programs\Python\Python311\Lib\site-packages\django\db\backends\sqlite3\base.py", line 354, in execute
    return super().execute(query, params)
           ^^^^^^^^^^^^^^^^^^^^^^^^^^^^^^
django.db.utils.IntegrityError: NOT NULL constraint failed: blog_test.owner_id
HTTP POST /api/tests/ 500 [0.16, 127.0.0.1:57274]